<?xml version="1.0" encoding="UTF-8"?>
<testng-results skipped="1" failed="2" ignored="0" total="8" passed="5">
  <reporter-output>
  </reporter-output>
  <suite name="Suite" duration-ms="32" started-at="2021-10-29T06:02:50Z" finished-at="2021-10-29T06:02:50Z">
    <groups>
    </groups>
    <test name="Test" duration-ms="32" started-at="2021-10-29T06:02:50Z" finished-at="2021-10-29T06:02:50Z">
      <class name="sample.DemoTest02">
        <test-method status="FAIL" signature="TestCase08()[pri:0, instance:sample.DemoTest02@7d9d1a19]" name="TestCase08" duration-ms="0" started-at="2021-10-29T06:02:50Z" finished-at="2021-10-29T06:02:50Z">
          <exception class="java.lang.AssertionError">
            <message>
              <![CDATA[expected [true] but found [false]]]>
            </message>
            <full-stacktrace>
              <![CDATA[java.lang.AssertionError: expected [true] but found [false]
at org.testng.Assert.fail(Assert.java:96)
at org.testng.Assert.failNotEquals(Assert.java:776)
at org.testng.Assert.assertTrue(Assert.java:44)
at org.testng.Assert.assertTrue(Assert.java:54)
at sample.DemoTest02.TestCase08(DemoTest02.java:28)
at sun.reflect.NativeMethodAccessorImpl.invoke0(Native Method)
at sun.reflect.NativeMethodAccessorImpl.invoke(Unknown Source)
at sun.reflect.DelegatingMethodAccessorImpl.invoke(Unknown Source)
at java.lang.reflect.Method.invoke(Unknown Source)
at org.testng.internal.MethodInvocationHelper.invokeMethod(MethodInvocationHelper.java:124)
at org.testng.internal.Invoker.invokeMethod(Invoker.java:583)
at org.testng.internal.Invoker.invokeTestMethod(Invoker.java:719)
at org.testng.internal.Invoker.invokeTestMethods(Invoker.java:989)
at org.testng.internal.TestMethodWorker.invokeTestMethods(TestMethodWorker.java:125)
at org.testng.internal.TestMethodWorker.run(TestMethodWorker.java:109)
at org.testng.TestRunner.privateRun(TestRunner.java:648)
at org.testng.TestRunner.run(TestRunner.java:505)
at org.testng.SuiteRunner.runTest(SuiteRunner.java:455)
at org.testng.SuiteRunner.runSequentially(SuiteRunner.java:450)
at org.testng.SuiteRunner.privateRun(SuiteRunner.java:415)
at org.testng.SuiteRunner.run(SuiteRunner.java:364)
at org.testng.SuiteRunnerWorker.runSuite(SuiteRunnerWorker.java:52)
at org.testng.SuiteRunnerWorker.run(SuiteRunnerWorker.java:84)
at org.testng.TestNG.runSuitesSequentially(TestNG.java:1208)
at org.testng.TestNG.runSuitesLocally(TestNG.java:1137)
at org.testng.TestNG.runSuites(TestNG.java:1049)
at org.testng.TestNG.run(TestNG.java:1017)
at org.testng.remote.AbstractRemoteTestNG.run(AbstractRemoteTestNG.java:114)
at org.testng.remote.RemoteTestNG.initAndRun(RemoteTestNG.java:251)
at org.testng.remote.RemoteTestNG.main(RemoteTestNG.java:77)
]]>
            </full-stacktrace>
          </exception> <!-- java.lang.AssertionError -->
          <reporter-output>
          </reporter-output>
        </test-method> <!-- TestCase08 -->
        <test-method status="PASS" signature="TestCase07()[pri:0, instance:sample.DemoTest02@7d9d1a19]" name="TestCase07" duration-ms="0" started-at="2021-10-29T06:02:50Z" finished-at="2021-10-29T06:02:50Z">
          <reporter-output>
          </reporter-output>
        </test-method> <!-- TestCase07 -->
        <test-method status="PASS" signature="TestCase06()[pri:0, instance:sample.DemoTest02@7d9d1a19]" name="TestCase06" duration-ms="0" started-at="2021-10-29T06:02:50Z" finished-at="2021-10-29T06:02:50Z">
          <reporter-output>
          </reporter-output>
        </test-method> <!-- TestCase06 -->
        <test-method status="SKIP" signature="TestCase09()[pri:0, instance:sample.DemoTest02@7d9d1a19]" name="TestCase09" duration-ms="0" started-at="2021-10-29T06:02:50Z" depends-on-methods="sample.DemoTest02.TestCase08" finished-at="2021-10-29T06:02:50Z">
          <exception class="java.lang.Throwable">
            <message>
              <![CDATA[Method DemoTest02.TestCase09()[pri:0, instance:sample.DemoTest02@7d9d1a19] depends on not successfully finished methods]]>
            </message>
            <full-stacktrace>
              <![CDATA[java.lang.Throwable: Method DemoTest02.TestCase09()[pri:0, instance:sample.DemoTest02@7d9d1a19] depends on not successfully finished methods
at org.testng.internal.Invoker.invokeTestMethods(Invoker.java:888)
at org.testng.internal.TestMethodWorker.invokeTestMethods(TestMethodWorker.java:125)
at org.testng.internal.TestMethodWorker.run(TestMethodWorker.java:109)
at org.testng.TestRunner.privateRun(TestRunner.java:648)
at org.testng.TestRunner.run(TestRunner.java:505)
at org.testng.SuiteRunner.runTest(SuiteRunner.java:455)
at org.testng.SuiteRunner.runSequentially(SuiteRunner.java:450)
at org.testng.SuiteRunner.privateRun(SuiteRunner.java:415)
at org.testng.SuiteRunner.run(SuiteRunner.java:364)
at org.testng.SuiteRunnerWorker.runSuite(SuiteRunnerWorker.java:52)
at org.testng.SuiteRunnerWorker.run(SuiteRunnerWorker.java:84)
at org.testng.TestNG.runSuitesSequentially(TestNG.java:1208)
at org.testng.TestNG.runSuitesLocally(TestNG.java:1137)
at org.testng.TestNG.runSuites(TestNG.java:1049)
at org.testng.TestNG.run(TestNG.java:1017)
at org.testng.remote.AbstractRemoteTestNG.run(AbstractRemoteTestNG.java:114)
at org.testng.remote.RemoteTestNG.initAndRun(RemoteTestNG.java:251)
at org.testng.remote.RemoteTestNG.main(RemoteTestNG.java:77)
]]>
            </full-stacktrace>
          </exception> <!-- java.lang.Throwable -->
          <reporter-output>
          </reporter-output>
        </test-method> <!-- TestCase09 -->
      </class> <!-- sample.DemoTest02 -->
      <class name="sample.DemoTest01">
        <test-method status="PASS" signature="TestCase01()[pri:0, instance:sample.DemoTest01@4883b407]" name="TestCase01" duration-ms="16" started-at="2021-10-29T06:02:50Z" finished-at="2021-10-29T06:02:50Z">
          <reporter-output>
          </reporter-output>
        </test-method> <!-- TestCase01 -->
        <test-method status="PASS" signature="TestCase04()[pri:0, instance:sample.DemoTest01@4883b407]" name="TestCase04" duration-ms="0" started-at="2021-10-29T06:02:50Z" finished-at="2021-10-29T06:02:50Z">
          <reporter-output>
          </reporter-output>
        </test-method> <!-- TestCase04 -->
        <test-method status="PASS" signature="TestCase02()[pri:0, instance:sample.DemoTest01@4883b407]" name="TestCase02" duration-ms="0" started-at="2021-10-29T06:02:50Z" finished-at="2021-10-29T06:02:50Z">
          <reporter-output>
          </reporter-output>
        </test-method> <!-- TestCase02 -->
        <test-method status="FAIL" signature="TestCase03()[pri:0, instance:sample.DemoTest01@4883b407]" name="TestCase03" duration-ms="0" started-at="2021-10-29T06:02:50Z" finished-at="2021-10-29T06:02:50Z">
          <exception class="java.lang.AssertionError">
            <message>
              <![CDATA[expected [true] but found [false]]]>
            </message>
            <full-stacktrace>
              <![CDATA[java.lang.AssertionError: expected [true] but found [false]
at org.testng.Assert.fail(Assert.java:96)
at org.testng.Assert.failNotEquals(Assert.java:776)
at org.testng.Assert.assertTrue(Assert.java:44)
at org.testng.Assert.assertTrue(Assert.java:54)
at sample.DemoTest01.TestCase03(DemoTest01.java:25)
at sun.reflect.NativeMethodAccessorImpl.invoke0(Native Method)
at sun.reflect.NativeMethodAccessorImpl.invoke(Unknown Source)
at sun.reflect.DelegatingMethodAccessorImpl.invoke(Unknown Source)
at java.lang.reflect.Method.invoke(Unknown Source)
at org.testng.internal.MethodInvocationHelper.invokeMethod(MethodInvocationHelper.java:124)
at org.testng.internal.Invoker.invokeMethod(Invoker.java:583)
at org.testng.internal.Invoker.invokeTestMethod(Invoker.java:719)
at org.testng.internal.Invoker.invokeTestMethods(Invoker.java:989)
at org.testng.internal.TestMethodWorker.invokeTestMethods(TestMethodWorker.java:125)
at org.testng.internal.TestMethodWorker.run(TestMethodWorker.java:109)
at org.testng.TestRunner.privateRun(TestRunner.java:648)
at org.testng.TestRunner.run(TestRunner.java:505)
at org.testng.SuiteRunner.runTest(SuiteRunner.java:455)
at org.testng.SuiteRunner.runSequentially(SuiteRunner.java:450)
at org.testng.SuiteRunner.privateRun(SuiteRunner.java:415)
at org.testng.SuiteRunner.run(SuiteRunner.java:364)
at org.testng.SuiteRunnerWorker.runSuite(SuiteRunnerWorker.java:52)
at org.testng.SuiteRunnerWorker.run(SuiteRunnerWorker.java:84)
at org.testng.TestNG.runSuitesSequentially(TestNG.java:1208)
at org.testng.TestNG.runSuitesLocally(TestNG.java:1137)
at org.testng.TestNG.runSuites(TestNG.java:1049)
at org.testng.TestNG.run(TestNG.java:1017)
at org.testng.remote.AbstractRemoteTestNG.run(AbstractRemoteTestNG.java:114)
at org.testng.remote.RemoteTestNG.initAndRun(RemoteTestNG.java:251)
at org.testng.remote.RemoteTestNG.main(RemoteTestNG.java:77)
]]>
            </full-stacktrace>
          </exception> <!-- java.lang.AssertionError -->
          <reporter-output>
          </reporter-output>
        </test-method> <!-- TestCase03 -->
      </class> <!-- sample.DemoTest01 -->
    </test> <!-- Test -->
  </suite> <!-- Suite -->
</testng-results>
